2018-10-31 16:36:26,692 ERROR: Exception on /edit_profile [POST] [in /Users/fuhongzhu/.virtualenvs/fuhzblog-O7aarCnf/lib/python3.6/site-packages/flask/app.py:1761]
Traceback (most recent call last):
  File "/Users/fuhongzhu/.virtualenvs/fuhzblog-O7aarCnf/lib/python3.6/site-packages/sqlalchemy/engine/base.py", line 1193, in _execute_context
    context)
  File "/Users/fuhongzhu/.virtualenvs/fuhzblog-O7aarCnf/lib/python3.6/site-packages/sqlalchemy/engine/default.py", line 509, in do_execute
    cursor.execute(statement, parameters)
sqlite3.IntegrityError: UNIQUE constraint failed: user.username

The above exception was the direct cause of the following exception:

Traceback (most recent call last):
  File "/Users/fuhongzhu/.virtualenvs/fuhzblog-O7aarCnf/lib/python3.6/site-packages/flask/app.py", line 2292, in wsgi_app
    response = self.full_dispatch_request()
  File "/Users/fuhongzhu/.virtualenvs/fuhzblog-O7aarCnf/lib/python3.6/site-packages/flask/app.py", line 1815, in full_dispatch_request
    rv = self.handle_user_exception(e)
  File "/Users/fuhongzhu/.virtualenvs/fuhzblog-O7aarCnf/lib/python3.6/site-packages/flask/app.py", line 1718, in handle_user_exception
    reraise(exc_type, exc_value, tb)
  File "/Users/fuhongzhu/.virtualenvs/fuhzblog-O7aarCnf/lib/python3.6/site-packages/flask/_compat.py", line 35, in reraise
    raise value
  File "/Users/fuhongzhu/.virtualenvs/fuhzblog-O7aarCnf/lib/python3.6/site-packages/flask/app.py", line 1813, in full_dispatch_request
    rv = self.dispatch_request()
  File "/Users/fuhongzhu/.virtualenvs/fuhzblog-O7aarCnf/lib/python3.6/site-packages/flask/app.py", line 1799, in dispatch_request
    return self.view_functions[rule.endpoint](**req.view_args)
  File "/Users/fuhongzhu/.virtualenvs/fuhzblog-O7aarCnf/lib/python3.6/site-packages/flask_login/utils.py", line 261, in decorated_view
    return func(*args, **kwargs)
  File "/Users/fuhongzhu/fuhzblog/app/routes.py", line 106, in edit_profile
    db.session.commit()
  File "/Users/fuhongzhu/.virtualenvs/fuhzblog-O7aarCnf/lib/python3.6/site-packages/sqlalchemy/orm/scoping.py", line 153, in do
    return getattr(self.registry(), name)(*args, **kwargs)
  File "/Users/fuhongzhu/.virtualenvs/fuhzblog-O7aarCnf/lib/python3.6/site-packages/sqlalchemy/orm/session.py", line 943, in commit
    self.transaction.commit()
  File "/Users/fuhongzhu/.virtualenvs/fuhzblog-O7aarCnf/lib/python3.6/site-packages/sqlalchemy/orm/session.py", line 467, in commit
    self._prepare_impl()
  File "/Users/fuhongzhu/.virtualenvs/fuhzblog-O7aarCnf/lib/python3.6/site-packages/sqlalchemy/orm/session.py", line 447, in _prepare_impl
    self.session.flush()
  File "/Users/fuhongzhu/.virtualenvs/fuhzblog-O7aarCnf/lib/python3.6/site-packages/sqlalchemy/orm/session.py", line 2254, in flush
    self._flush(objects)
  File "/Users/fuhongzhu/.virtualenvs/fuhzblog-O7aarCnf/lib/python3.6/site-packages/sqlalchemy/orm/session.py", line 2380, in _flush
    transaction.rollback(_capture_exception=True)
  File "/Users/fuhongzhu/.virtualenvs/fuhzblog-O7aarCnf/lib/python3.6/site-packages/sqlalchemy/util/langhelpers.py", line 66, in __exit__
    compat.reraise(exc_type, exc_value, exc_tb)
  File "/Users/fuhongzhu/.virtualenvs/fuhzblog-O7aarCnf/lib/python3.6/site-packages/sqlalchemy/util/compat.py", line 249, in reraise
    raise value
  File "/Users/fuhongzhu/.virtualenvs/fuhzblog-O7aarCnf/lib/python3.6/site-packages/sqlalchemy/orm/session.py", line 2344, in _flush
    flush_context.execute()
  File "/Users/fuhongzhu/.virtualenvs/fuhzblog-O7aarCnf/lib/python3.6/site-packages/sqlalchemy/orm/unitofwork.py", line 391, in execute
    rec.execute(self)
  File "/Users/fuhongzhu/.virtualenvs/fuhzblog-O7aarCnf/lib/python3.6/site-packages/sqlalchemy/orm/unitofwork.py", line 556, in execute
    uow
  File "/Users/fuhongzhu/.virtualenvs/fuhzblog-O7aarCnf/lib/python3.6/site-packages/sqlalchemy/orm/persistence.py", line 177, in save_obj
    mapper, table, update)
  File "/Users/fuhongzhu/.virtualenvs/fuhzblog-O7aarCnf/lib/python3.6/site-packages/sqlalchemy/orm/persistence.py", line 768, in _emit_update_statements
    execute(statement, multiparams)
  File "/Users/fuhongzhu/.virtualenvs/fuhzblog-O7aarCnf/lib/python3.6/site-packages/sqlalchemy/engine/base.py", line 948, in execute
    return meth(self, multiparams, params)
  File "/Users/fuhongzhu/.virtualenvs/fuhzblog-O7aarCnf/lib/python3.6/site-packages/sqlalchemy/sql/elements.py", line 269, in _execute_on_connection
    return connection._execute_clauseelement(self, multiparams, params)
  File "/Users/fuhongzhu/.virtualenvs/fuhzblog-O7aarCnf/lib/python3.6/site-packages/sqlalchemy/engine/base.py", line 1060, in _execute_clauseelement
    compiled_sql, distilled_params
  File "/Users/fuhongzhu/.virtualenvs/fuhzblog-O7aarCnf/lib/python3.6/site-packages/sqlalchemy/engine/base.py", line 1200, in _execute_context
    context)
  File "/Users/fuhongzhu/.virtualenvs/fuhzblog-O7aarCnf/lib/python3.6/site-packages/sqlalchemy/engine/base.py", line 1413, in _handle_dbapi_exception
    exc_info
  File "/Users/fuhongzhu/.virtualenvs/fuhzblog-O7aarCnf/lib/python3.6/site-packages/sqlalchemy/util/compat.py", line 265, in raise_from_cause
    reraise(type(exception), exception, tb=exc_tb, cause=cause)
  File "/Users/fuhongzhu/.virtualenvs/fuhzblog-O7aarCnf/lib/python3.6/site-packages/sqlalchemy/util/compat.py", line 248, in reraise
    raise value.with_traceback(tb)
  File "/Users/fuhongzhu/.virtualenvs/fuhzblog-O7aarCnf/lib/python3.6/site-packages/sqlalchemy/engine/base.py", line 1193, in _execute_context
    context)
  File "/Users/fuhongzhu/.virtualenvs/fuhzblog-O7aarCnf/lib/python3.6/site-packages/sqlalchemy/engine/default.py", line 509, in do_execute
    cursor.execute(statement, parameters)
sqlalchemy.exc.IntegrityError: (sqlite3.IntegrityError) UNIQUE constraint failed: user.username [SQL: 'UPDATE user SET username=?, about_me=? WHERE user.id = ?'] [parameters: ('wuqiufeng', 'flask blog  舞秋风flask blog  舞秋风flask blog  舞秋风flask blog  舞秋风flask blog  舞秋风flask blog  舞秋风', 2)] (Background on this error at: http://sqlalche.me/e/gkpj)
2018-10-31 17:40:04,545 INFO: Microblog startup [in /Users/fuhongzhu/fuhzblog/app/__init__.py:55]
2018-10-31 18:12:04,215 INFO: Microblog startup [in /Users/fuhongzhu/fuhzblog/app/__init__.py:55]
2018-10-31 18:12:29,332 INFO: Microblog startup [in /Users/fuhongzhu/fuhzblog/app/__init__.py:55]
2018-10-31 18:28:23,611 INFO: Microblog startup [in /Users/fuhongzhu/fuhzblog/app/__init__.py:55]
2018-10-31 18:40:15,852 INFO: Microblog startup [in /Users/fuhongzhu/fuhzblog/app/__init__.py:55]
2018-10-31 18:46:24,901 INFO: Microblog startup [in /Users/fuhongzhu/fuhzblog/app/__init__.py:55]
2018-10-31 18:51:25,930 INFO: Microblog startup [in /Users/fuhongzhu/fuhzblog/app/__init__.py:55]
2018-10-31 18:58:22,878 INFO: Microblog startup [in /Users/fuhongzhu/fuhzblog/app/__init__.py:55]
2018-10-31 19:08:23,140 INFO: Microblog startup [in /Users/fuhongzhu/fuhzblog/app/__init__.py:55]
2018-10-31 19:13:31,235 INFO: Microblog startup [in /Users/fuhongzhu/fuhzblog/app/__init__.py:55]
2018-11-01 10:47:58,274 INFO: Microblog startup [in /Users/fuhongzhu/fuhzblog/app/__init__.py:55]
2018-11-01 11:01:37,855 INFO: Microblog startup [in /Users/fuhongzhu/fuhzblog/app/__init__.py:55]
2018-11-01 11:31:23,392 INFO: Microblog startup [in /Users/fuhongzhu/fuhzblog/app/__init__.py:55]
2018-11-01 11:31:48,197 ERROR: Exception on /reset_password_request [POST] [in /Users/fuhongzhu/.virtualenvs/fuhzblog-O7aarCnf/lib/python3.6/site-packages/flask/app.py:1761]
Traceback (most recent call last):
  File "/Users/fuhongzhu/.virtualenvs/fuhzblog-O7aarCnf/lib/python3.6/site-packages/flask/app.py", line 2292, in wsgi_app
    response = self.full_dispatch_request()
  File "/Users/fuhongzhu/.virtualenvs/fuhzblog-O7aarCnf/lib/python3.6/site-packages/flask/app.py", line 1815, in full_dispatch_request
    rv = self.handle_user_exception(e)
  File "/Users/fuhongzhu/.virtualenvs/fuhzblog-O7aarCnf/lib/python3.6/site-packages/flask/app.py", line 1718, in handle_user_exception
    reraise(exc_type, exc_value, tb)
  File "/Users/fuhongzhu/.virtualenvs/fuhzblog-O7aarCnf/lib/python3.6/site-packages/flask/_compat.py", line 35, in reraise
    raise value
  File "/Users/fuhongzhu/.virtualenvs/fuhzblog-O7aarCnf/lib/python3.6/site-packages/flask/app.py", line 1813, in full_dispatch_request
    rv = self.dispatch_request()
  File "/Users/fuhongzhu/.virtualenvs/fuhzblog-O7aarCnf/lib/python3.6/site-packages/flask/app.py", line 1799, in dispatch_request
    return self.view_functions[rule.endpoint](**req.view_args)
  File "/Users/fuhongzhu/fuhzblog/app/routes.py", line 208, in reset_password_request
    send_password_reset_email(user)
NameError: name 'send_password_reset_email' is not defined
2018-11-01 11:33:21,491 INFO: Microblog startup [in /Users/fuhongzhu/fuhzblog/app/__init__.py:55]
